<?xml version="1.0" encoding="utf-8"?>
<!-- This URDF was automatically created by SolidWorks to URDF Exporter! Originally created by Stephen Brawner (brawner@gmail.com) 
     Commit Version: 1.6.0-1-g15f4949  Build Version: 1.6.7594.29634
     For more information, please see http://wiki.ros.org/sw_urdf_exporter -->
<robot
  name="mybot_description">
  <link
    name="base_link">
    <inertial>
      <origin
        xyz="0.128386820110742 0.000686929395924185 0.158512775795314"
        rpy="0 0 0" />
      <mass
        value="34.6383267278588" />
      <inertia
        ixx="1.73796264850436"
        ixy="-0.000148699799662171"
        ixz="-0.260070022561171"
        iyy="2.13507888591353"
        iyz="-1.80220424604975E-06"
        izz="2.01858956817808" />
    </inertial>
    <visual>
      <origin
        xyz="0 0 0"
        rpy="0 0 0" />
      <geometry>
        <mesh
          filename="package://mybot_description/meshes/base_link.STL" />
      </geometry>
      <material
        name="">
        <color
          rgba="0.792156862745098 0.819607843137255 0.933333333333333 1" />
      </material>
    </visual>
    <collision>
      <origin
        xyz="0 0 0"
        rpy="0 0 0" />
      <geometry>
        <mesh
          filename="package://mybot_description/meshes/base_link.STL" />
      </geometry>
    </collision>
  </link>
  <link
    name="right_motor">
    <inertial>
      <origin
        xyz="-4.20679424628645E-09 0.0331497387034929 4.87590441966557E-06"
        rpy="0 0 0" />
      <mass
        value="1.43144480602327" />
      <inertia
        ixx="0.00331965861699229"
        ixy="-1.65643316648922E-10"
        ixz="-2.49861743707994E-10"
        iyy="0.00595557706241426"
        iyz="-3.90156064036137E-07"
        izz="0.00331969353968102" />
    </inertial>
    <visual>
      <origin
        xyz="0 0 0"
        rpy="0 0 0" />
      <geometry>
        <mesh
          filename="package://mybot_description/meshes/right_motor.STL" />
      </geometry>
      <material
        name="">
        <color
          rgba="0.792156862745098 0.819607843137255 0.933333333333333 1" />
      </material>
    </visual>
    <collision>
      <origin
        xyz="0 0 0"
        rpy="0 0 0" />
      <geometry>
        <mesh
          filename="package://mybot_description/meshes/right_motor.STL" />
      </geometry>
    </collision>
  </link>
  <joint
    name="right_motor_joint"
    type="continuous">
    <origin
      xyz="0.21185 -0.327 -0.242"
      rpy="0 0 0" />
    <parent
      link="base_link" />
    <child
      link="right_motor" />
    <axis
      xyz="0 -1 0" />
  </joint>
  <link
    name="left_motor">
    <inertial>
      <origin
        xyz="-4.20679446833105E-09 0.0331497387034928 4.87590441999863E-06"
        rpy="0 0 0" />
      <mass
        value="1.43144480602327" />
      <inertia
        ixx="0.00331965861699228"
        ixy="-1.65643329348428E-10"
        ixz="-2.49861736040813E-10"
        iyy="0.00595557706241427"
        iyz="-3.90156064035793E-07"
        izz="0.00331969353968103" />
    </inertial>
    <visual>
      <origin
        xyz="0 0 0"
        rpy="0 0 0" />
      <geometry>
        <mesh
          filename="package://mybot_description/meshes/left_motor.STL" />
      </geometry>
      <material
        name="">
        <color
          rgba="0.792156862745098 0.819607843137255 0.933333333333333 1" />
      </material>
    </visual>
    <collision>
      <origin
        xyz="0 0 0"
        rpy="0 0 0" />
      <geometry>
        <mesh
          filename="package://mybot_description/meshes/left_motor.STL" />
      </geometry>
    </collision>
  </link>
  <joint
    name="left_motor_joint"
    type="continuous">
    <origin
      xyz="0.21185 0.327 -0.242"
      rpy="0 0 3.1416" />
    <parent
      link="base_link" />
    <child
      link="left_motor" />
    <axis
      xyz="0 1 0" />
  </joint>
  <link
    name="right_wheel">
    <inertial>
      <origin
        xyz="4.2067941907753E-09 0.0331497387034929 -4.87590441988761E-06"
        rpy="0 0 0" />
      <mass
        value="1.43144480602327" />
      <inertia
        ixx="0.00331965861699229"
        ixy="1.65643316113872E-10"
        ixz="-2.49861736302478E-10"
        iyy="0.00595557706241427"
        iyz="3.9015606403935E-07"
        izz="0.00331969353968102" />
    </inertial>
    <visual>
      <origin
        xyz="0 0 0"
        rpy="0 0 0" />
      <geometry>
        <mesh
          filename="package://mybot_description/meshes/right_wheel.STL" />
      </geometry>
      <material
        name="">
        <color
          rgba="0.792156862745098 0.819607843137255 0.933333333333333 1" />
      </material>
    </visual>
    <collision>
      <origin
        xyz="0 0 0"
        rpy="0 0 0" />
      <geometry>
        <mesh
          filename="package://mybot_description/meshes/right_wheel.STL" />
      </geometry>
    </collision>
  </link>
  <joint
    name="right_wheel_joint"
    type="continuous">
    <origin
      xyz="-0.063147 -0.327 -0.242"
      rpy="0 0 0" />
    <parent
      link="base_link" />
    <child
      link="right_wheel" />
    <axis
      xyz="0 -1 0" />
  </joint>
  <link
    name="left_wheel">
    <inertial>
      <origin
        xyz="4.20679427404202E-09 0.0331497387034928 -4.87590441961006E-06"
        rpy="0 0 0" />
      <mass
        value="1.43144480602327" />
      <inertia
        ixx="0.0033196586169923"
        ixy="1.65643308665796E-10"
        ixz="-2.49861736506603E-10"
        iyy="0.00595557706241428"
        iyz="3.90156064036769E-07"
        izz="0.00331969353968103" />
    </inertial>
    <visual>
      <origin
        xyz="0 0 0"
        rpy="0 0 0" />
      <geometry>
        <mesh
          filename="package://mybot_description/meshes/left_wheel.STL" />
      </geometry>
      <material
        name="">
        <color
          rgba="0.792156862745098 0.819607843137255 0.933333333333333 1" />
      </material>
    </visual>
    <collision>
      <origin
        xyz="0 0 0"
        rpy="0 0 0" />
      <geometry>
        <mesh
          filename="package://mybot_description/meshes/left_wheel.STL" />
      </geometry>
    </collision>
  </link>
  <joint
    name="left_wheel_joint"
    type="continuous">
    <origin
      xyz="-0.063147 0.327 -0.242"
      rpy="0 0 3.1416" />
    <parent
      link="base_link" />
    <child
      link="left_wheel" />
    <axis
      xyz="0 1 0" />
  </joint>
  <link
    name="camera_link">
    <inertial>
      <origin
        xyz="-0.0277735063558892 0.0143658806531268 5.94217075544634E-09"
        rpy="0 0 0" />
      <mass
        value="0.554061895865926" />
      <inertia
        ixx="0.00292760923931499"
        ixy="-9.3576574546003E-07"
        ixz="-9.73024378416661E-11"
        iyy="0.00022646595658487"
        iyz="-4.83501853093787E-10"
        izz="0.00302698572685721" />
    </inertial>
    <visual>
      <origin
        xyz="0 0 0"
        rpy="0 0 0" />
      <geometry>
        <mesh
          filename="package://mybot_description/meshes/camera_link.STL" />
      </geometry>
      <material
        name="">
        <color
          rgba="0.494117647058824 0.494117647058824 0.494117647058824 1" />
      </material>
    </visual>
    <collision>
      <origin
        xyz="0 0 0"
        rpy="0 0 0" />
      <geometry>
        <mesh
          filename="package://mybot_description/meshes/camera_link.STL" />
      </geometry>
    </collision>
  </link>
  <joint
    name="kinect_joint"
    type="fixed">
    <origin
      xyz="0.49448 -0.016314 0.10959"
      rpy="0 0 0" />
    <parent
      link="base_link" />
    <child
      link="camera_link" />
    <axis
      xyz="0 0 0" />
  </joint>

<!--Kinect  Link /-->


  <!--  Kinect Optical Link and joints   /-->
<joint name="kinect_optical_joint" type="fixed">

<origin xyz="0 0 0" rpy="-1.5707 0 -1.5707"/> <!-- To invert the coordinates from image convention (Z is forward) to normal xyz /-->
<parent link="camera_link"/>
<child link="kinect_optical"/>
</joint>

<!--Virtual link to project the images to, and then flip it to us as its joint is flipped  /-->
<link name="kinect_optical">
</link>
</robot>